"""The error handler for the application."""

import os
import sys
import traceback
from collections.abc import Mapping, Set
from sqlite3 import Error as SqliteError
from typing import Any, Optional, Protocol, TypeVar, Union

import httpx
import jwt
from asyncpg import exceptions as postgres_exceptions
from pydantic import ValidationError as PydanticValidationError
from sanic import HTTPResponse, Request, SanicException, json
from sanic.errorpages import BaseRenderer, TextRenderer
from sanic.handlers import ErrorHandler
from sanic_ext.exceptions import ValidationError
from sqlalchemy.exc import SQLAlchemyError

from renku_data_services import errors


class BaseError(Protocol):
    """Protocol for the error type of an apispec module."""

    code: int
    message: str
    detail: Optional[str]
    quiet: bool


class BaseErrorResponse(Protocol):
    """Protocol for the error response class of an apispec module."""

    error: BaseError

    def dict(
        self,
        *,
        include: Optional[Union[Set[Union[int, str]], Mapping[Union[int, str], Any]]] = None,
        exclude: Optional[Union[Set[Union[int, str]], Mapping[Union[int, str], Any]]] = None,
        by_alias: bool = False,
        skip_defaults: Optional[bool] = None,
        exclude_unset: bool = False,
        exclude_defaults: bool = False,
        exclude_none: bool = False,
    ) -> dict[str, Any]:
        """Turn the response to dict."""
        ...


BError = TypeVar("BError", bound=BaseError)
BErrorResponse = TypeVar("BErrorResponse", bound=BaseErrorResponse)


class ApiSpec(Protocol[BErrorResponse, BError]):
    """Protocol for an apispec with error data."""

    ErrorResponse: BErrorResponse
    Error: BError


class CustomErrorHandler(ErrorHandler):
    """Central error handling."""

    def __init__(self, api_spec: ApiSpec, base: type[BaseRenderer] = TextRenderer) -> None:
        self.api_spec = api_spec
        super().__init__(base)

    @classmethod
    def _get_formatted_exception(cls, exception: Exception) -> errors.BaseError | None:
        formatted_exception: errors.BaseError | None = None
        match exception:
            case errors.BaseError():
                formatted_exception = exception
            case ValidationError():
                extra_exception = None if exception.extra is None else exception.extra["exception"]
                match extra_exception:
                    case TypeError():
                        formatted_exception = errors.ValidationError(
                            message="The validation failed because the provided input has the wrong type"
                        )
                    case PydanticValidationError():
                        parts = [
                            ".".join(str(i) for i in field["loc"]) + ": " + field["msg"]
                            for field in extra_exception.errors()
                        ]
                        message = f"There are errors in the following fields, {', '.join(parts)}"
                        formatted_exception = errors.ValidationError(message=message)
            case SanicException():
                message = exception.message
                if message == "" or message is None:
                    message = ", ".join([str(i) for i in exception.args])
                formatted_exception = errors.BaseError(
                    message=message,
                    status_code=exception.status_code,
                    code=1000 + exception.status_code,
                    quiet=exception.quiet or False,
                )
            case SqliteError():
                formatted_exception = errors.BaseError(
                    message=f"Database error occurred: {exception.sqlite_errorname}",
                    detail=f"Error code: {exception.sqlite_errorcode}",
                )
            case postgres_exceptions.PostgresError():
                formatted_exception = errors.BaseError(
                    message=f"Database error occurred: {exception.msg}", detail=f"Error code: {exception.pgcode}"
                )
            case SQLAlchemyError():
                message = ", ".join([str(i) for i in exception.args])
                if "CharacterNotInRepertoireError" in message:
                    # NOTE: This message is usually triggered if a string field for the database contains
                    # NULL - i.e \u0000 or other invalid characters that are not UTF-8 compatible
                    formatted_exception = errors.ValidationError(
                        message="The payload contains characters that are incompatible with the database",
                        detail=message,
                    )
                elif "value out of int32 range" in message:
                    formatted_exception = errors.ValidationError(
                        message="The payload contains integers with values that are "
                        "too large or small for the database",
                        detail=message,
                    )
                else:
                    formatted_exception = errors.BaseError(message=f"Database error occurred: {message}")
            case PydanticValidationError():
                parts = [".".join(str(i) for i in field["loc"]) + ": " + field["msg"] for field in exception.errors()]
                message = f"There are errors in the following fields, {', '.join(parts)}"
                formatted_exception = errors.ValidationError(message=message)
            case OverflowError():
                formatted_exception = errors.ValidationError(
                    message="The provided input is too large to be stored in the database"
                )
            case jwt.exceptions.InvalidTokenError():
                formatted_exception = errors.InvalidTokenError()

            case httpx.RequestError():
                formatted_exception = errors.BaseError(message=f"Error on remote connection: {exception}")

        return formatted_exception

    def default(self, request: Request, exception: Exception) -> HTTPResponse:
        """Overrides the default error handler."""
        formatted_exception = self._get_formatted_exception(exception) or errors.BaseError()

        self.log(request, formatted_exception)
        if formatted_exception.status_code == 500 and "PYTEST_CURRENT_TEST" in os.environ:
            # TODO: Figure out how to do logging properly in here, I could not get the sanic logs to show up from here
            # at all when running schemathesis. So 500 errors are hard to debug but print statements do show up.
            # The above log statement does not show up in the logs that pytest shows after a test is done.
            sys.stderr.write(f"A 500 error was raised because of {type(exception)} on request {request}\n")
            traceback.print_exception(exception)
        return json(
            self.api_spec.ErrorResponse(
                error=self.api_spec.Error(
                    code=formatted_exception.code,
                    message=formatted_exception.message,
                    detail=formatted_exception.detail,
                )
            ).model_dump(exclude_none=True),
            status=formatted_exception.status_code,
        )
